CRITICAL - 2024-12-22 22:14:38,440  -main.py - Database connection error, the greenlet library is required to use this function. No module named 'greenlet'
ERROR - 2024-12-22 22:14:38,441  -get_session.py - Session rollback, exception: 500: Error connecting to the database
CRITICAL - 2024-12-22 22:15:01,759  -main.py - Database connection error, the greenlet library is required to use this function. No module named 'greenlet'
ERROR - 2024-12-22 22:15:01,759  -get_session.py - Session rollback, exception: 500: Error connecting to the database
CRITICAL - 2024-12-22 22:15:08,730  -main.py - Database connection error, the greenlet library is required to use this function. No module named 'greenlet'
ERROR - 2024-12-22 22:15:08,730  -get_session.py - Session rollback, exception: 500: Error connecting to the database
ERROR - 2024-12-22 22:15:49,294  -get_session.py - Session rollback, exception: 'str' object has no attribute 'as_tuple'
ERROR - 2024-12-22 22:18:17,612  -get_session.py - Session rollback, exception: 'firtst_name' is an invalid keyword argument for Contacts
ERROR - 2024-12-22 22:19:24,457  -get_session.py - Session rollback, exception: Instance '<Contacts at 0x105f26990>' is not persistent within this Session
ERROR - 2024-12-22 22:19:50,382  -get_session.py - Session rollback, exception: Instance '<Contacts at 0x104ffe750>' is not persistent within this Session
ERROR - 2024-12-22 22:24:01,116  -get_session.py - Session rollback, exception: (sqlalchemy.dialects.postgresql.asyncpg.IntegrityError) <class 'asyncpg.exceptions.NotNullViolationError'>: null value in column "date_birthday" violates not-null constraint
DETAIL:  Failing row contains (1, string, string, user@example.com, string, null, string, 2024-12-22 20:24:01.112307, 2024-12-22 20:24:01.112307, null).
[SQL: INSERT INTO contacts (first_name, last_name, email, phone_number, date_birthday, note, created_at, updated_at, users_id) VALUES ($1::VARCHAR, $2::VARCHAR, $3::VARCHAR, $4::VARCHAR, $5::DATE, $6::VARCHAR, now(), now(), $7::INTEGER) RETURNING contacts.id, contacts.created_at, contacts.updated_at]
[parameters: ('string', 'string', 'user@example.com', 'string', None, 'string', None)]
(Background on this error at: https://sqlalche.me/e/20/gkpj)
ERROR - 2024-12-22 22:26:21,829  -get_session.py - Session rollback, exception: (sqlalchemy.dialects.postgresql.asyncpg.IntegrityError) <class 'asyncpg.exceptions.NotNullViolationError'>: null value in column "date_birthday" violates not-null constraint
DETAIL:  Failing row contains (2, string, string, user@example.com, string, null, string, 2024-12-22 20:26:21.8272, 2024-12-22 20:26:21.8272, null).
[SQL: INSERT INTO contacts (first_name, last_name, email, phone_number, date_birthday, note, created_at, updated_at, users_id) VALUES ($1::VARCHAR, $2::VARCHAR, $3::VARCHAR, $4::VARCHAR, $5::DATE, $6::VARCHAR, now(), now(), $7::INTEGER) RETURNING contacts.id, contacts.created_at, contacts.updated_at]
[parameters: ('string', 'string', 'user@example.com', 'string', None, 'string', None)]
(Background on this error at: https://sqlalche.me/e/20/gkpj)
ERROR - 2024-12-22 22:30:13,834  -get_session.py - Session rollback, exception: (sqlalchemy.dialects.postgresql.asyncpg.IntegrityError) <class 'asyncpg.exceptions.NotNullViolationError'>: null value in column "date_birthday" violates not-null constraint
DETAIL:  Failing row contains (3, string, string, user@example.com, string, null, string, 2024-12-22 20:30:13.829713, 2024-12-22 20:30:13.829713).
[SQL: INSERT INTO contacts (first_name, last_name, email, phone_number, date_birthday, note, created_at, updated_at) VALUES ($1::VARCHAR, $2::VARCHAR, $3::VARCHAR, $4::VARCHAR, $5::DATE, $6::VARCHAR, now(), now()) RETURNING contacts.id, contacts.created_at, contacts.updated_at]
[parameters: ('string', 'string', 'user@example.com', 'string', None, 'string')]
(Background on this error at: https://sqlalche.me/e/20/gkpj)
ERROR - 2024-12-23 10:09:19,185  -get_session.py - Session rollback, exception: 1 validation errors:
  {'type': 'model_attributes_type', 'loc': ('response',), 'msg': 'Input should be a valid dictionary or object to extract fields from', 'input': None}

ERROR - 2024-12-23 10:11:30,302  -get_session.py - Session rollback, exception: 1 validation errors:
  {'type': 'model_attributes_type', 'loc': ('response',), 'msg': 'Input should be a valid dictionary or object to extract fields from', 'input': None}

ERROR - 2024-12-23 10:12:12,896  -get_session.py - Session rollback, exception: 1 validation errors:
  {'type': 'model_attributes_type', 'loc': ('response',), 'msg': 'Input should be a valid dictionary or object to extract fields from', 'input': None}

ERROR - 2024-12-23 10:15:24,704  -get_session.py - Session rollback, exception: 404: not found 
ERROR - 2024-12-23 10:47:01,747  -get_session.py - Session rollback, exception: 'AsyncSession' object has no attribute 'referfh'
ERROR - 2024-12-23 10:58:32,811  -get_session.py - Session rollback, exception: module 'app.repository.contacts' has no attribute 'delete_contact'
ERROR - 2024-12-23 13:35:48,946  -get_session.py - Session rollback, exception: bcrypt: no backends available -- recommend you install one (e.g. 'pip install bcrypt')
INFO - 2024-12-23 13:36:57,911  -email_serv.py - token type email_token
INFO - 2024-12-23 13:36:57,924  -email_serv.py - Sending email task to RabbitMQ: {'email': 'user@example.com', 'username': 'string', 'host': 'http://127.0.0.1:8000/', 'queue_name': 'confirm email', 'token': 'eyJhbGciOiJIUzI1NiIsInR5cCI6IkpXVCJ9.eyJzdWIiOiJ1c2VyQGV4YW1wbGUuY29tIiwiZXhwIjoxNzM0OTk3MDE3LCJpYXQiOjE3MzQ5NTM4MTcsInNjb3BlIjoiZW1haWxfdG9rZW4ifQ.g3ZQX4XpifdICOeU_Jln1q_o8HKvD5b0z_i35cBf-Fk'} 
INFO - 2024-12-23 13:36:57,924  -produse.py - Preparing to send message to RabbitMQ
INFO - 2024-12-23 13:36:57,952  -get_rab_con.py - rabbitmq conn TRUE
INFO - 2024-12-23 13:36:57,952  -get_rab_con.py - Using RabbitMQ connection
INFO - 2024-12-23 13:36:57,960  -produse.py - Message published to RabbitMQ with routing_key 'confirm email
INFO - 2024-12-23 13:36:57,962  -get_rab_con.py - rabbotmq connection closed
WARNING - 2024-12-23 13:37:03,731  -auth.py - user already exists in database
ERROR - 2024-12-23 13:37:03,731  -get_session.py - Session rollback, exception: 409: account already exists
INFO - 2024-12-23 16:05:40,073  -worker.py - Starting worker...
INFO - 2024-12-23 16:05:40,084  -get_rab_con.py - rabbitmq conn TRUE
INFO - 2024-12-23 16:05:40,084  -get_rab_con.py - Using RabbitMQ connection
INFO - 2024-12-23 16:05:40,095  -worker.py - Worker is consuming messages...
INFO - 2024-12-23 16:06:08,711  -get_rab_con.py - rabbotmq connection closed
